2021-04-03 17:05:21 [scrapy] DEBUG: Crawled (200) <GET https://www.microcenter.com/robots.txt> (referer: None)
2021-04-03 17:05:21 [scrapy] DEBUG: Crawled (200) <GET https://www.microcenter.com/search/search_results.aspx?N=4294966937&NTK=all&sortby=match&rpp=24> (referer: None)
2021-04-03 17:05:21 [scrapy] DEBUG: Crawled (200) <GET https://www.microcenter.com/search/search_results.aspx?Ntk=all&sortby=match&N=4294966654&myStore=false> (referer: None)
2021-04-03 17:05:21 [scrapy] DEBUG: Crawled (200) <GET https://www.microcenter.com/category/4294945779/ssd-solid-state-drives> (referer: None)
2021-04-03 17:05:21 [scrapy] DEBUG: Crawled (200) <GET https://www.microcenter.com/search/search_results.aspx?Ntk=all&sortby=match&N=4294964318&myStore=false> (referer: None)
2021-04-03 17:05:22 [scrapy] DEBUG: Crawled (200) <GET https://www.microcenter.com/search/search_results.aspx?N=4294966937&NTK=all&page=2&cat=Video-Cards-:-MicroCenter> (referer: https://www.microcenter.com/search/search_results.aspx?N=4294966937&NTK=all&sortby=match&rpp=24)
2021-04-03 17:05:22 [scrapy] DEBUG: Crawled (200) <GET https://www.microcenter.com/search/search_results.aspx?N=4294945779&NTK=all&page=2&cat=SSD-(Solid-State-Drives)-:-MicroCenter> (referer: https://www.microcenter.com/category/4294945779/ssd-solid-state-drives)
2021-04-03 17:05:22 [scrapy] DEBUG: Crawled (200) <GET https://www.microcenter.com/search/search_results.aspx?N=4294966654&NTK=all&page=2&cat=Power-Supplies-:-MicroCenter> (referer: https://www.microcenter.com/search/search_results.aspx?Ntk=all&sortby=match&N=4294966654&myStore=false)
2021-04-03 17:05:22 [scrapy] DEBUG: Crawled (200) <GET https://www.microcenter.com/search/search_results.aspx?N=4294964318&NTK=all&page=2&cat=Computer-Cases-:-MicroCenter> (referer: https://www.microcenter.com/search/search_results.aspx?Ntk=all&sortby=match&N=4294964318&myStore=false)
2021-04-03 17:05:22 [scrapy] DEBUG: Crawled (200) <GET https://www.microcenter.com/search/search_results.aspx?N=4294966937&NTK=all&page=3&cat=Video-Cards-:-MicroCenter> (referer: https://www.microcenter.com/search/search_results.aspx?N=4294966937&NTK=all&page=2&cat=Video-Cards-:-MicroCenter)
2021-04-03 17:05:22 [scrapy] DEBUG: Crawled (200) <GET https://www.microcenter.com/search/search_results.aspx?N=4294945779&NTK=all&page=1&cat=SSD-(Solid-State-Drives)-:-MicroCenter> (referer: https://www.microcenter.com/search/search_results.aspx?N=4294945779&NTK=all&page=2&cat=SSD-(Solid-State-Drives)-:-MicroCenter)
2021-04-03 17:05:22 [scrapy] DEBUG: Crawled (200) <GET https://www.microcenter.com/search/search_results.aspx?N=4294966654&NTK=all&page=3&cat=Power-Supplies-:-MicroCenter> (referer: https://www.microcenter.com/search/search_results.aspx?N=4294966654&NTK=all&page=2&cat=Power-Supplies-:-MicroCenter)
2021-04-03 17:05:22 [scrapy] ERROR: Error processing {'href': 'https://www.microcenter.comhttps://www.microcenter.com/product/627080/seagate-barracuda-q1-960gb-ssd-3d-qlc-nand-sata-iii-6gb-s-25-internal-solid-state-drive',
 'img': 'https://90a1c75758623581b3f8-5c119c3de181c9857fcb2784776b17ef.ssl.cf2.rackcdn.com/0627080_159640.jpg',
 'name': 'BarraCuda Q1 960GB SSD 3D QLC NAND SATA III 6Gb/s 2.5&quot; Internal '
         'Solid State Drive',
 'part_type': 'SSD (Solid State Drives)',
 'price': 99.99,
 'rating': 0.0}
Traceback (most recent call last):
  File "/Library/Frameworks/Python.framework/Versions/3.7/lib/python3.7/site-packages/sqlalchemy/engine/base.py", line 1277, in _execute_context
    cursor, statement, parameters, context
  File "/Library/Frameworks/Python.framework/Versions/3.7/lib/python3.7/site-packages/sqlalchemy/engine/default.py", line 593, in do_execute
    cursor.execute(statement, parameters)
sqlite3.OperationalError: table pc-part has no column named rating

The above exception was the direct cause of the following exception:

Traceback (most recent call last):
  File "/Library/Frameworks/Python.framework/Versions/3.7/lib/python3.7/site-packages/twisted/internet/defer.py", line 662, in _runCallbacks
    current.result = callback(current.result, *args, **kw)
  File "/Library/Frameworks/Python.framework/Versions/3.7/lib/python3.7/site-packages/scrapy/utils/defer.py", line 150, in f
    return deferred_from_coro(coro_f(*coro_args, **coro_kwargs))
  File "/Users/robert/Desktop/Python Projects/PC-Generator-Backend/pc_generator/pipelines.py", line 45, in process_item
    session.commit()
  File "/Library/Frameworks/Python.framework/Versions/3.7/lib/python3.7/site-packages/sqlalchemy/orm/session.py", line 1042, in commit
    self.transaction.commit()
  File "/Library/Frameworks/Python.framework/Versions/3.7/lib/python3.7/site-packages/sqlalchemy/orm/session.py", line 504, in commit
    self._prepare_impl()
  File "/Library/Frameworks/Python.framework/Versions/3.7/lib/python3.7/site-packages/sqlalchemy/orm/session.py", line 483, in _prepare_impl
    self.session.flush()
  File "/Library/Frameworks/Python.framework/Versions/3.7/lib/python3.7/site-packages/sqlalchemy/orm/session.py", line 2536, in flush
    self._flush(objects)
  File "/Library/Frameworks/Python.framework/Versions/3.7/lib/python3.7/site-packages/sqlalchemy/orm/session.py", line 2678, in _flush
    transaction.rollback(_capture_exception=True)
  File "/Library/Frameworks/Python.framework/Versions/3.7/lib/python3.7/site-packages/sqlalchemy/util/langhelpers.py", line 70, in __exit__
    with_traceback=exc_tb,
  File "/Library/Frameworks/Python.framework/Versions/3.7/lib/python3.7/site-packages/sqlalchemy/util/compat.py", line 182, in raise_
    raise exception
  File "/Library/Frameworks/Python.framework/Versions/3.7/lib/python3.7/site-packages/sqlalchemy/orm/session.py", line 2638, in _flush
    flush_context.execute()
  File "/Library/Frameworks/Python.framework/Versions/3.7/lib/python3.7/site-packages/sqlalchemy/orm/unitofwork.py", line 422, in execute
    rec.execute(self)
  File "/Library/Frameworks/Python.framework/Versions/3.7/lib/python3.7/site-packages/sqlalchemy/orm/unitofwork.py", line 589, in execute
    uow,
  File "/Library/Frameworks/Python.framework/Versions/3.7/lib/python3.7/site-packages/sqlalchemy/orm/persistence.py", line 245, in save_obj
    insert,
  File "/Library/Frameworks/Python.framework/Versions/3.7/lib/python3.7/site-packages/sqlalchemy/orm/persistence.py", line 1136, in _emit_insert_statements
    statement, params
  File "/Library/Frameworks/Python.framework/Versions/3.7/lib/python3.7/site-packages/sqlalchemy/engine/base.py", line 1011, in execute
    return meth(self, multiparams, params)
  File "/Library/Frameworks/Python.framework/Versions/3.7/lib/python3.7/site-packages/sqlalchemy/sql/elements.py", line 298, in _execute_on_connection
    return connection._execute_clauseelement(self, multiparams, params)
  File "/Library/Frameworks/Python.framework/Versions/3.7/lib/python3.7/site-packages/sqlalchemy/engine/base.py", line 1130, in _execute_clauseelement
    distilled_params,
  File "/Library/Frameworks/Python.framework/Versions/3.7/lib/python3.7/site-packages/sqlalchemy/engine/base.py", line 1317, in _execute_context
    e, statement, parameters, cursor, context
  File "/Library/Frameworks/Python.framework/Versions/3.7/lib/python3.7/site-packages/sqlalchemy/engine/base.py", line 1511, in _handle_dbapi_exception
    sqlalchemy_exception, with_traceback=exc_info[2], from_=e
  File "/Library/Frameworks/Python.framework/Versions/3.7/lib/python3.7/site-packages/sqlalchemy/util/compat.py", line 182, in raise_
    raise exception
  File "/Library/Frameworks/Python.framework/Versions/3.7/lib/python3.7/site-packages/sqlalchemy/engine/base.py", line 1277, in _execute_context
    cursor, statement, parameters, context
  File "/Library/Frameworks/Python.framework/Versions/3.7/lib/python3.7/site-packages/sqlalchemy/engine/default.py", line 593, in do_execute
    cursor.execute(statement, parameters)
sqlalchemy.exc.OperationalError: (sqlite3.OperationalError) table pc-part has no column named rating
[SQL: INSERT INTO "pc-part" (name, price, href, img, part_type, rating) VALUES (?, ?, ?, ?, ?, ?)]
[parameters: ('BarraCuda Q1 960GB SSD 3D QLC NAND SATA III 6Gb/s 2.5&quot; Internal Solid State Drive', 99.99, 'https://www.microcenter.comhttps://www.microcenter.com/product/627080/seagate-barracuda-q1-960gb-ssd-3d-qlc-nand-sata-iii-6gb-s-25-internal-solid-state-drive', 'https://90a1c75758623581b3f8-5c119c3de181c9857fcb2784776b17ef.ssl.cf2.rackcdn.com/0627080_159640.jpg', 'SSD (Solid State Drives)', 0.0)]
(Background on this error at: http://sqlalche.me/e/13/e3q8)
2021-04-03 17:05:23 [scrapy] DEBUG: Crawled (200) <GET https://www.microcenter.com/search/search_results.aspx?N=4294964318&NTK=all&page=3&cat=Computer-Cases-:-MicroCenter> (referer: https://www.microcenter.com/search/search_results.aspx?N=4294964318&NTK=all&page=2&cat=Computer-Cases-:-MicroCenter)
2021-04-03 17:05:23 [scrapy] DEBUG: Crawled (200) <GET https://www.microcenter.com/search/search_results.aspx?N=4294966937&NTK=all&page=4&cat=Video-Cards-:-MicroCenter> (referer: https://www.microcenter.com/search/search_results.aspx?N=4294966937&NTK=all&page=3&cat=Video-Cards-:-MicroCenter)
2021-04-03 17:05:23 [scrapy] DEBUG: Crawled (200) <GET https://www.microcenter.com/search/search_results.aspx?N=4294966654&NTK=all&page=4&cat=Power-Supplies-:-MicroCenter> (referer: https://www.microcenter.com/search/search_results.aspx?N=4294966654&NTK=all&page=3&cat=Power-Supplies-:-MicroCenter)
2021-04-03 17:05:23 [scrapy] ERROR: Error processing {'href': 'https://www.microcenter.comhttps://www.microcenter.com/product/485312/powerspec-650-watt-80-plus-bronze-atx-semi-modular-power-supply',
 'img': 'https://90a1c75758623581b3f8-5c119c3de181c9857fcb2784776b17ef.ssl.cf2.rackcdn.com/0485312_402404.jpg',
 'name': '650 Watt 80 Plus Bronze ATX Semi-Modular Power Supply',
 'part_type': 'Power Supplies',
 'price': 69.99,
 'rating': 0.0}
Traceback (most recent call last):
  File "/Library/Frameworks/Python.framework/Versions/3.7/lib/python3.7/site-packages/sqlalchemy/engine/base.py", line 1277, in _execute_context
    cursor, statement, parameters, context
  File "/Library/Frameworks/Python.framework/Versions/3.7/lib/python3.7/site-packages/sqlalchemy/engine/default.py", line 593, in do_execute
    cursor.execute(statement, parameters)
sqlite3.OperationalError: table pc-part has no column named rating

The above exception was the direct cause of the following exception:

Traceback (most recent call last):
  File "/Library/Frameworks/Python.framework/Versions/3.7/lib/python3.7/site-packages/twisted/internet/defer.py", line 662, in _runCallbacks
    current.result = callback(current.result, *args, **kw)
  File "/Library/Frameworks/Python.framework/Versions/3.7/lib/python3.7/site-packages/scrapy/utils/defer.py", line 150, in f
    return deferred_from_coro(coro_f(*coro_args, **coro_kwargs))
  File "/Users/robert/Desktop/Python Projects/PC-Generator-Backend/pc_generator/pipelines.py", line 45, in process_item
    session.commit()
  File "/Library/Frameworks/Python.framework/Versions/3.7/lib/python3.7/site-packages/sqlalchemy/orm/session.py", line 1042, in commit
    self.transaction.commit()
  File "/Library/Frameworks/Python.framework/Versions/3.7/lib/python3.7/site-packages/sqlalchemy/orm/session.py", line 504, in commit
    self._prepare_impl()
  File "/Library/Frameworks/Python.framework/Versions/3.7/lib/python3.7/site-packages/sqlalchemy/orm/session.py", line 483, in _prepare_impl
    self.session.flush()
  File "/Library/Frameworks/Python.framework/Versions/3.7/lib/python3.7/site-packages/sqlalchemy/orm/session.py", line 2536, in flush
    self._flush(objects)
  File "/Library/Frameworks/Python.framework/Versions/3.7/lib/python3.7/site-packages/sqlalchemy/orm/session.py", line 2678, in _flush
    transaction.rollback(_capture_exception=True)
  File "/Library/Frameworks/Python.framework/Versions/3.7/lib/python3.7/site-packages/sqlalchemy/util/langhelpers.py", line 70, in __exit__
    with_traceback=exc_tb,
  File "/Library/Frameworks/Python.framework/Versions/3.7/lib/python3.7/site-packages/sqlalchemy/util/compat.py", line 182, in raise_
    raise exception
  File "/Library/Frameworks/Python.framework/Versions/3.7/lib/python3.7/site-packages/sqlalchemy/orm/session.py", line 2638, in _flush
    flush_context.execute()
  File "/Library/Frameworks/Python.framework/Versions/3.7/lib/python3.7/site-packages/sqlalchemy/orm/unitofwork.py", line 422, in execute
    rec.execute(self)
  File "/Library/Frameworks/Python.framework/Versions/3.7/lib/python3.7/site-packages/sqlalchemy/orm/unitofwork.py", line 589, in execute
    uow,
  File "/Library/Frameworks/Python.framework/Versions/3.7/lib/python3.7/site-packages/sqlalchemy/orm/persistence.py", line 245, in save_obj
    insert,
  File "/Library/Frameworks/Python.framework/Versions/3.7/lib/python3.7/site-packages/sqlalchemy/orm/persistence.py", line 1136, in _emit_insert_statements
    statement, params
  File "/Library/Frameworks/Python.framework/Versions/3.7/lib/python3.7/site-packages/sqlalchemy/engine/base.py", line 1011, in execute
    return meth(self, multiparams, params)
  File "/Library/Frameworks/Python.framework/Versions/3.7/lib/python3.7/site-packages/sqlalchemy/sql/elements.py", line 298, in _execute_on_connection
    return connection._execute_clauseelement(self, multiparams, params)
  File "/Library/Frameworks/Python.framework/Versions/3.7/lib/python3.7/site-packages/sqlalchemy/engine/base.py", line 1130, in _execute_clauseelement
    distilled_params,
  File "/Library/Frameworks/Python.framework/Versions/3.7/lib/python3.7/site-packages/sqlalchemy/engine/base.py", line 1317, in _execute_context
    e, statement, parameters, cursor, context
  File "/Library/Frameworks/Python.framework/Versions/3.7/lib/python3.7/site-packages/sqlalchemy/engine/base.py", line 1511, in _handle_dbapi_exception
    sqlalchemy_exception, with_traceback=exc_info[2], from_=e
  File "/Library/Frameworks/Python.framework/Versions/3.7/lib/python3.7/site-packages/sqlalchemy/util/compat.py", line 182, in raise_
    raise exception
  File "/Library/Frameworks/Python.framework/Versions/3.7/lib/python3.7/site-packages/sqlalchemy/engine/base.py", line 1277, in _execute_context
    cursor, statement, parameters, context
  File "/Library/Frameworks/Python.framework/Versions/3.7/lib/python3.7/site-packages/sqlalchemy/engine/default.py", line 593, in do_execute
    cursor.execute(statement, parameters)
sqlalchemy.exc.OperationalError: (sqlite3.OperationalError) table pc-part has no column named rating
[SQL: INSERT INTO "pc-part" (name, price, href, img, part_type, rating) VALUES (?, ?, ?, ?, ?, ?)]
[parameters: ('650 Watt 80 Plus Bronze ATX Semi-Modular Power Supply', 69.99, 'https://www.microcenter.comhttps://www.microcenter.com/product/485312/powerspec-650-watt-80-plus-bronze-atx-semi-modular-power-supply', 'https://90a1c75758623581b3f8-5c119c3de181c9857fcb2784776b17ef.ssl.cf2.rackcdn.com/0485312_402404.jpg', 'Power Supplies', 0.0)]
(Background on this error at: http://sqlalche.me/e/13/e3q8)
2021-04-03 17:05:23 [scrapy] DEBUG: Crawled (200) <GET https://www.microcenter.com/search/search_results.aspx?N=4294964318&NTK=all&page=4&cat=Computer-Cases-:-MicroCenter> (referer: https://www.microcenter.com/search/search_results.aspx?N=4294964318&NTK=all&page=3&cat=Computer-Cases-:-MicroCenter)
2021-04-03 17:05:23 [scrapy] DEBUG: Crawled (200) <GET https://www.microcenter.com/search/search_results.aspx?N=4294966937&NTK=all&page=5&cat=Video-Cards-:-MicroCenter> (referer: https://www.microcenter.com/search/search_results.aspx?N=4294966937&NTK=all&page=4&cat=Video-Cards-:-MicroCenter)
2021-04-03 17:05:23 [scrapy] ERROR: Error processing {'href': 'https://www.microcenter.comhttps://www.microcenter.com/product/604789/lian-li-205-tempered-glass-atx-computer-case---black',
 'img': 'https://90a1c75758623581b3f8-5c119c3de181c9857fcb2784776b17ef.ssl.cf2.rackcdn.com/0604789_908012.jpg',
 'name': '205 Tempered Glass ATX Computer Case - Black',
 'part_type': 'Computer Cases',
 'price': 69.99,
 'rating': 0.0}
Traceback (most recent call last):
  File "/Library/Frameworks/Python.framework/Versions/3.7/lib/python3.7/site-packages/sqlalchemy/engine/base.py", line 1277, in _execute_context
    cursor, statement, parameters, context
  File "/Library/Frameworks/Python.framework/Versions/3.7/lib/python3.7/site-packages/sqlalchemy/engine/default.py", line 593, in do_execute
    cursor.execute(statement, parameters)
sqlite3.OperationalError: table pc-part has no column named rating

The above exception was the direct cause of the following exception:

Traceback (most recent call last):
  File "/Library/Frameworks/Python.framework/Versions/3.7/lib/python3.7/site-packages/twisted/internet/defer.py", line 662, in _runCallbacks
    current.result = callback(current.result, *args, **kw)
  File "/Library/Frameworks/Python.framework/Versions/3.7/lib/python3.7/site-packages/scrapy/utils/defer.py", line 150, in f
    return deferred_from_coro(coro_f(*coro_args, **coro_kwargs))
  File "/Users/robert/Desktop/Python Projects/PC-Generator-Backend/pc_generator/pipelines.py", line 45, in process_item
    session.commit()
  File "/Library/Frameworks/Python.framework/Versions/3.7/lib/python3.7/site-packages/sqlalchemy/orm/session.py", line 1042, in commit
    self.transaction.commit()
  File "/Library/Frameworks/Python.framework/Versions/3.7/lib/python3.7/site-packages/sqlalchemy/orm/session.py", line 504, in commit
    self._prepare_impl()
  File "/Library/Frameworks/Python.framework/Versions/3.7/lib/python3.7/site-packages/sqlalchemy/orm/session.py", line 483, in _prepare_impl
    self.session.flush()
  File "/Library/Frameworks/Python.framework/Versions/3.7/lib/python3.7/site-packages/sqlalchemy/orm/session.py", line 2536, in flush
    self._flush(objects)
  File "/Library/Frameworks/Python.framework/Versions/3.7/lib/python3.7/site-packages/sqlalchemy/orm/session.py", line 2678, in _flush
    transaction.rollback(_capture_exception=True)
  File "/Library/Frameworks/Python.framework/Versions/3.7/lib/python3.7/site-packages/sqlalchemy/util/langhelpers.py", line 70, in __exit__
    with_traceback=exc_tb,
  File "/Library/Frameworks/Python.framework/Versions/3.7/lib/python3.7/site-packages/sqlalchemy/util/compat.py", line 182, in raise_
    raise exception
  File "/Library/Frameworks/Python.framework/Versions/3.7/lib/python3.7/site-packages/sqlalchemy/orm/session.py", line 2638, in _flush
    flush_context.execute()
  File "/Library/Frameworks/Python.framework/Versions/3.7/lib/python3.7/site-packages/sqlalchemy/orm/unitofwork.py", line 422, in execute
    rec.execute(self)
  File "/Library/Frameworks/Python.framework/Versions/3.7/lib/python3.7/site-packages/sqlalchemy/orm/unitofwork.py", line 589, in execute
    uow,
  File "/Library/Frameworks/Python.framework/Versions/3.7/lib/python3.7/site-packages/sqlalchemy/orm/persistence.py", line 245, in save_obj
    insert,
  File "/Library/Frameworks/Python.framework/Versions/3.7/lib/python3.7/site-packages/sqlalchemy/orm/persistence.py", line 1136, in _emit_insert_statements
    statement, params
  File "/Library/Frameworks/Python.framework/Versions/3.7/lib/python3.7/site-packages/sqlalchemy/engine/base.py", line 1011, in execute
    return meth(self, multiparams, params)
  File "/Library/Frameworks/Python.framework/Versions/3.7/lib/python3.7/site-packages/sqlalchemy/sql/elements.py", line 298, in _execute_on_connection
    return connection._execute_clauseelement(self, multiparams, params)
  File "/Library/Frameworks/Python.framework/Versions/3.7/lib/python3.7/site-packages/sqlalchemy/engine/base.py", line 1130, in _execute_clauseelement
    distilled_params,
  File "/Library/Frameworks/Python.framework/Versions/3.7/lib/python3.7/site-packages/sqlalchemy/engine/base.py", line 1317, in _execute_context
    e, statement, parameters, cursor, context
  File "/Library/Frameworks/Python.framework/Versions/3.7/lib/python3.7/site-packages/sqlalchemy/engine/base.py", line 1511, in _handle_dbapi_exception
    sqlalchemy_exception, with_traceback=exc_info[2], from_=e
  File "/Library/Frameworks/Python.framework/Versions/3.7/lib/python3.7/site-packages/sqlalchemy/util/compat.py", line 182, in raise_
    raise exception
  File "/Library/Frameworks/Python.framework/Versions/3.7/lib/python3.7/site-packages/sqlalchemy/engine/base.py", line 1277, in _execute_context
    cursor, statement, parameters, context
  File "/Library/Frameworks/Python.framework/Versions/3.7/lib/python3.7/site-packages/sqlalchemy/engine/default.py", line 593, in do_execute
    cursor.execute(statement, parameters)
sqlalchemy.exc.OperationalError: (sqlite3.OperationalError) table pc-part has no column named rating
[SQL: INSERT INTO "pc-part" (name, price, href, img, part_type, rating) VALUES (?, ?, ?, ?, ?, ?)]
[parameters: ('205 Tempered Glass ATX Computer Case - Black', 69.99, 'https://www.microcenter.comhttps://www.microcenter.com/product/604789/lian-li-205-tempered-glass-atx-computer-case---black', 'https://90a1c75758623581b3f8-5c119c3de181c9857fcb2784776b17ef.ssl.cf2.rackcdn.com/0604789_908012.jpg', 'Computer Cases', 0.0)]
(Background on this error at: http://sqlalche.me/e/13/e3q8)
2021-04-03 17:05:24 [scrapy] DEBUG: Crawled (200) <GET https://www.microcenter.com/search/search_results.aspx?N=4294966937&NTK=all&page=6&cat=Video-Cards-:-MicroCenter> (referer: https://www.microcenter.com/search/search_results.aspx?N=4294966937&NTK=all&page=5&cat=Video-Cards-:-MicroCenter)
2021-04-03 17:05:24 [scrapy] DEBUG: Crawled (200) <GET https://www.microcenter.com/search/search_results.aspx?N=4294966937&NTK=all&page=7&cat=Video-Cards-:-MicroCenter> (referer: https://www.microcenter.com/search/search_results.aspx?N=4294966937&NTK=all&page=6&cat=Video-Cards-:-MicroCenter)
2021-04-03 17:05:25 [scrapy] ERROR: Error processing {'href': 'https://www.microcenter.comhttps://www.microcenter.com/product/604243/msi-geforce-gtx-1660-ventus-xs-overclocked-dual-fan-6gb-gddr5-pcie-30-graphics-card',
 'img': 'https://90a1c75758623581b3f8-5c119c3de181c9857fcb2784776b17ef.ssl.cf2.rackcdn.com/0604243_906792.jpg',
 'name': 'GeForce GTX 1660 Ventus XS Overclocked Dual-Fan 6GB GDDR5 PCIe 3.0 '
         'Graphics Card',
 'part_type': 'Video Cards',
 'price': 334.99,
 'rating': 0.0}
Traceback (most recent call last):
  File "/Library/Frameworks/Python.framework/Versions/3.7/lib/python3.7/site-packages/sqlalchemy/engine/base.py", line 1277, in _execute_context
    cursor, statement, parameters, context
  File "/Library/Frameworks/Python.framework/Versions/3.7/lib/python3.7/site-packages/sqlalchemy/engine/default.py", line 593, in do_execute
    cursor.execute(statement, parameters)
sqlite3.OperationalError: table pc-part has no column named rating

The above exception was the direct cause of the following exception:

Traceback (most recent call last):
  File "/Library/Frameworks/Python.framework/Versions/3.7/lib/python3.7/site-packages/twisted/internet/defer.py", line 662, in _runCallbacks
    current.result = callback(current.result, *args, **kw)
  File "/Library/Frameworks/Python.framework/Versions/3.7/lib/python3.7/site-packages/scrapy/utils/defer.py", line 150, in f
    return deferred_from_coro(coro_f(*coro_args, **coro_kwargs))
  File "/Users/robert/Desktop/Python Projects/PC-Generator-Backend/pc_generator/pipelines.py", line 45, in process_item
    session.commit()
  File "/Library/Frameworks/Python.framework/Versions/3.7/lib/python3.7/site-packages/sqlalchemy/orm/session.py", line 1042, in commit
    self.transaction.commit()
  File "/Library/Frameworks/Python.framework/Versions/3.7/lib/python3.7/site-packages/sqlalchemy/orm/session.py", line 504, in commit
    self._prepare_impl()
  File "/Library/Frameworks/Python.framework/Versions/3.7/lib/python3.7/site-packages/sqlalchemy/orm/session.py", line 483, in _prepare_impl
    self.session.flush()
  File "/Library/Frameworks/Python.framework/Versions/3.7/lib/python3.7/site-packages/sqlalchemy/orm/session.py", line 2536, in flush
    self._flush(objects)
  File "/Library/Frameworks/Python.framework/Versions/3.7/lib/python3.7/site-packages/sqlalchemy/orm/session.py", line 2678, in _flush
    transaction.rollback(_capture_exception=True)
  File "/Library/Frameworks/Python.framework/Versions/3.7/lib/python3.7/site-packages/sqlalchemy/util/langhelpers.py", line 70, in __exit__
    with_traceback=exc_tb,
  File "/Library/Frameworks/Python.framework/Versions/3.7/lib/python3.7/site-packages/sqlalchemy/util/compat.py", line 182, in raise_
    raise exception
  File "/Library/Frameworks/Python.framework/Versions/3.7/lib/python3.7/site-packages/sqlalchemy/orm/session.py", line 2638, in _flush
    flush_context.execute()
  File "/Library/Frameworks/Python.framework/Versions/3.7/lib/python3.7/site-packages/sqlalchemy/orm/unitofwork.py", line 422, in execute
    rec.execute(self)
  File "/Library/Frameworks/Python.framework/Versions/3.7/lib/python3.7/site-packages/sqlalchemy/orm/unitofwork.py", line 589, in execute
    uow,
  File "/Library/Frameworks/Python.framework/Versions/3.7/lib/python3.7/site-packages/sqlalchemy/orm/persistence.py", line 245, in save_obj
    insert,
  File "/Library/Frameworks/Python.framework/Versions/3.7/lib/python3.7/site-packages/sqlalchemy/orm/persistence.py", line 1136, in _emit_insert_statements
    statement, params
  File "/Library/Frameworks/Python.framework/Versions/3.7/lib/python3.7/site-packages/sqlalchemy/engine/base.py", line 1011, in execute
    return meth(self, multiparams, params)
  File "/Library/Frameworks/Python.framework/Versions/3.7/lib/python3.7/site-packages/sqlalchemy/sql/elements.py", line 298, in _execute_on_connection
    return connection._execute_clauseelement(self, multiparams, params)
  File "/Library/Frameworks/Python.framework/Versions/3.7/lib/python3.7/site-packages/sqlalchemy/engine/base.py", line 1130, in _execute_clauseelement
    distilled_params,
  File "/Library/Frameworks/Python.framework/Versions/3.7/lib/python3.7/site-packages/sqlalchemy/engine/base.py", line 1317, in _execute_context
    e, statement, parameters, cursor, context
  File "/Library/Frameworks/Python.framework/Versions/3.7/lib/python3.7/site-packages/sqlalchemy/engine/base.py", line 1511, in _handle_dbapi_exception
    sqlalchemy_exception, with_traceback=exc_info[2], from_=e
  File "/Library/Frameworks/Python.framework/Versions/3.7/lib/python3.7/site-packages/sqlalchemy/util/compat.py", line 182, in raise_
    raise exception
  File "/Library/Frameworks/Python.framework/Versions/3.7/lib/python3.7/site-packages/sqlalchemy/engine/base.py", line 1277, in _execute_context
    cursor, statement, parameters, context
  File "/Library/Frameworks/Python.framework/Versions/3.7/lib/python3.7/site-packages/sqlalchemy/engine/default.py", line 593, in do_execute
    cursor.execute(statement, parameters)
sqlalchemy.exc.OperationalError: (sqlite3.OperationalError) table pc-part has no column named rating
[SQL: INSERT INTO "pc-part" (name, price, href, img, part_type, rating) VALUES (?, ?, ?, ?, ?, ?)]
[parameters: ('GeForce GTX 1660 Ventus XS Overclocked Dual-Fan 6GB GDDR5 PCIe 3.0 Graphics Card', 334.99, 'https://www.microcenter.comhttps://www.microcenter.com/product/604243/msi-geforce-gtx-1660-ventus-xs-overclocked-dual-fan-6gb-gddr5-pcie-30-graphics-card', 'https://90a1c75758623581b3f8-5c119c3de181c9857fcb2784776b17ef.ssl.cf2.rackcdn.com/0604243_906792.jpg', 'Video Cards', 0.0)]
(Background on this error at: http://sqlalche.me/e/13/e3q8)
2021-04-03 17:05:25 [scrapy] INFO: Closing spider (finished)
2021-04-03 17:05:25 [scrapy] INFO: Dumping Scrapy stats:
{'downloader/request_bytes': 8408,
 'downloader/request_count': 19,
 'downloader/request_method_count/GET': 19,
 'downloader/response_bytes': 1056746,
 'downloader/response_count': 19,
 'downloader/response_status_count/200': 19,
 'elapsed_time_seconds': 4.267659,
 'finish_reason': 'finished',
 'finish_time': datetime.datetime(2021, 4, 4, 0, 5, 25, 64855),
 'log_count/DEBUG': 19,
 'log_count/ERROR': 4,
 'log_count/INFO': 7,
 'memusage/max': 96317440,
 'memusage/startup': 96317440,
 'request_depth_max': 6,
 'response_received_count': 19,
 'robotstxt/request_count': 1,
 'robotstxt/response_count': 1,
 'robotstxt/response_status_count/200': 1,
 'scheduler/dequeued': 18,
 'scheduler/dequeued/memory': 18,
 'scheduler/enqueued': 18,
 'scheduler/enqueued/memory': 18,
 'start_time': datetime.datetime(2021, 4, 4, 0, 5, 20, 797196)}
2021-04-03 17:05:25 [scrapy] INFO: Spider closed (finished)
